Workbook

Sheet Products
K1: Product titel | O1: Specificaties | S1: Beschrijving (lang) | W1: USP | AA1: Productinformatie (kort) | AE1: Gerelateerde producten | AF1: Foto's FTP | AG1: Productgroepen AG
A2: Artikel | B2: Omschrijving | C2: Sharon.Hoogland | D2: Administratie | E2: Supplier | H2: Verkoopprijs | I2: Hoofdcategorie | J2: Subcategorie | K2: Artikelnaam | L2: TD - Titel DE | M2: TE - Titel Engels | N2: TF - Titel Frans | O2: SN - Specificatie NL | P2: SD - Specificatie DE | Q2: SE - Specificatie EN | R2: SF - Specificatie FR | S2: BN - Beschrijving NL | T2: BD - Beschrijving DE | U2: BE - Beschrijving Engels | V2: BF - Bechrijving Frans | W2: UN - USP NL | X2: UD - USP DE | Y2: UE - USP Engels | Z2: UF - USP FR | AA2: IN - Productinfo NL | AB2: ID - Productinfo DE | AC2: IE - Productinfo EN | AD2: IF - Productinfo FR | AE2: 4x Artikelcode gescheiden door ; | AF2: Aantallen aangeven | AG2: ZG | AH2: WG | AI2: UG
A3: 1213652DE | B3: Hartpapierhülse 1400 x 154 x 125 mm | C3: 0,000 | D3: 37, Tip Top | E3: 12022, REMA TIP TOP AG | F3: Actief | G3: 4,140 | I3: x | J3: x | AG3: 081
A4: 232086-KERNKLOSLL | B4: Kernklos - 250/105-70 | C4: 0,000 | D4: 34, Verbruikte materialen | F4: Actief | G4: 1,950 | I4: x | J4: x | AG4: 083
A5: 5000043PM | B5: REMA TIP TOP Binnenbandpleister 1 35 mm 30 stuks | C5: 0,000 | D5: 37, Tip Top | E5: 17842, Rema Tip Top Nederland B.V. | F5: Actief | G5: 3,260 | I5: x | J5: x | AG5: 083
A6: 5061982DE | B6: T-Rex Hot Vulc+ 0,5 kg | C6: 0,000 | D6: 37, Tip Top | E6: 12022, REMA TIP TOP AG | F6: Actief | G6: 7,800 | H6: 16.5 | I6: 06_Vulcanization Materials | J6: 06-04_T-Rex Glue for Hot Vulcanization | K6: T-REX Hot Vulc+ ; Lijm voor Warmvulkanisatie | L6: T-REX Hot Vulc+ ; Kleber für Heißverbindung | M6: T-REX Hot Vulc+ ; Glue for Hot Vulcanization | N6: T-REX Hot Vulc+ ; Colle pour vulcanisation à chaud | O6: Blik 0,7 Liter / 0,5 Kg | P6: Dose 0,7 Liter / 0,5 Kg | Q6: Can 0,7 Liter / 0,5 Kg | R6: Pot 0,7 Litre / 0,5 Kg | S6: Gemiddeld verbruik per vierkante meter transportband (alleen richtwaarden) ; 1e laag = ca. 300 g/m2 ; 2e laag = ca. 280 g/m2 ; * afhankelijk van het type weefsel ; ; Overeenkomstig de verordening (EG) nr. 1907/2006 (REACH) bevat dit product geen PBT / vPvB-substanties | T6: Durchschnittlicher Verbrauch pro Quadratmeter Förderband (nur Richtwerte) ; 1. Auftrag = ca. 300g/m² ; 2. Auftrag = ca. 280g/m² ; * abhängig von dem Type des Gewebes | U6: Average consumption per square meter of conveyor belt (guideline values only) ; 1st coat = approx. 300 g/m2 ; 2nd coat = approx. 280 g/m2 ; * depending on the type of belt fabric | V6: Consommation moyenne par mètre carré de bande transporteuse (valeurs indicatives uniquement) ; 1ère couche = env. 300 g/m2 ; 2ème couche = env. 280g/m2 ; * selon le type de tissu de la ceinture | W6: CHC-vrij; Gevaarlijke goederen: Ja; Voor Standaard, K en HR kwaliteit dekrubber ; | X6: Ckw-frei ; Gefahrengut: Ja ; Für Gummideckplatten Standard-, K- und HR-Qualität ; | Y6: CHC-Free ; Dangerous goods: Yes ; For Standard, K and HR quality cover rubber ; | Z6: Sans CHC ; Marchandises dangereuses : Oui ; Pour revêtement en caoutchouc de qualité Standard, K et HR ; | AA6: Lijm voor Warmvulkanisatie ; | AB6: Kleber für die Heißvulkanisation ; | AC6: Glue for hot vulcanization ; | AD6: Colle pour vulcanisation à chaud ; | AE6: 5061983DE ; TUSSENRUBBER-0,8SP ; DEKRUBBER-2MMSP ; TOOL003-KWASTTS | AF6: 5061982DE-1 ; 5061982DE-2 | AG6: 081 | AH6: 090 | AI6: 081 | AJ6: WAGU Heizlösung WTHZN
A7: 5061983DE | B7: T-Rex Hot Vulc+ 3,5 kg | C7: 0,000 | D7: 37, Tip Top | E7: 12022, REMA TIP TOP AG | F7: Actief | G7: 45,300 | H7: 85 | I7: 06_Vulcanization Materials | J7: 06-04_T-Rex Glue for Hot Vulcanization | K7: T-REX Hot Vulc+ ; Lijm voor Warmvulkanisatie | L7: T-REX Hot Vulc+ ; Kleber für Heißverbindung | M7: T-REX Hot Vulc+ ; Glue for Hot Vulcanization | N7: T-REX Hot Vulc+ ; Colle pour vulcanisation à chaud | O7: Emmer 5 Liter / 3,5 Kg | P7: Kanne 5 Liter / 3,5 Kg | Q7: Bucket 5 Liter / 3,5 Kg | R7: Seau 5 Litre / 3,5 Kg | S7: Gemiddeld verbruik per vierkante meter transportband (alleen richtwaarden) ; 1e laag = ca. 300 g/m2 ; 2e laag = ca. 280 g/m2 ; * afhankelijk van het type weefsel ; ; Overeenkomstig de verordening (EG) nr. 1907/2006 (REACH) bevat dit product geen PBT / vPvB-substanties | T7: Durchschnittlicher Verbrauch pro Quadratmeter Förderband (nur Richtwerte) ; 1. Anstrich = ca. 300g/m2 ; 2. Anstrich = ca. 280g/m2 ; * abhängig von dem Type des Gewebes | U7: Average consumption per square meter of conveyor belt (guideline values only) ; 1st coat = approx. 300 g/m2 ; 2nd coat = approx. 280 g/m2 ; * depending on the type of belt fabric | V7: Consommation moyenne par mètre carré de bande transporteuse (valeurs indicatives uniquement) ; 1ère couche = env. 300 g/m2 ; 2ème couche = env. 280g/m2 ; * selon le type de tissu de la ceinture | W7: CHC-vrij; Gevaarlijke goederen: Ja; Voor Standaard, K en HR kwaliteit dekrubber ; | X7: Ckw-frei ; Gefahrengut: Ja ; Für Gummideckplatten Standard-, K- und HR-Qualität ; | Y7: CHC-Free ; Dangerous goods: Yes ; For Standard, K and HR quality cover rubber ; | Z7: Sans CHC ; Marchandises dangereuses : Oui ; Pour revêtement en caoutchouc de qualité Standard, K et HR ; | AA7: Lijm voor Warmvulkanisatie ; | AB7: Kleber für die Heißvulkanisation ; | AC7: Glue for hot vulcanization ; | AD7: Colle pour vulcanisation à chaud ; | AE7: 5061982DE ; TUSSENRUBBER-0,8SP ; DEKRUBBER-2MMSP ; TOOL003-KWASTTS | AF7: 5061983DE-1 | AG7: 081 | AH7: 090 | AI7: 081 | AJ7: WAGU Heizlösung WTHZN
A8: 5061984DE | B8: T-Rex Cleaner 5 liter | C8: 0,000 | D8: 37, Tip Top | E8: 12022, REMA TIP TOP AG | F8: Actief | G8: 29,450 | H8: 51.5 | I8: 06_Vulcanization Materials | J8: 06-01_T-Rex Cleaner | K8: T-Rex Cleaner | L8: T-Rex Reinigung | M8: T-Rex Cleaner | N8: T-Rex Nettoyage | O8: Blik 5 liter | P8: Kanne 5 Liter | Q8: Can 5 liter | R8: Pot 5 liter | S8: Reinigingsmiddel om vet en vuil van rubber te verwijderen om een ​​schone omgeving te creëren voor sterke hechting. ; Voor universeel gebruik met CHC-vrije lijmsystemen, primers, vulkaniseer- en verwarmingsoplossingen. ; Kan worden gebruikt als spray voor het nauwkeurig reinigen van kleine oppervlakken. | T8: Reinigungsmittel zum Entfernen von Fett und Schmutz von Gummi, um eine saubere Umgebung für eine starke Haftung zu schaffen. ; Für den universellen Einsatz mit CKW-freien Klebstoffsystemen, Primern, Vulkanisier- und Heizlösungen. ; Kann als Spray zur präzisen Reinigung kleiner Flächen verwendet werden. | U8: Cleaning solvent to remove grease and dirt from rubber to provide a clean environment for strong adhesion ; For universal use with CHC-free adhesive systems, primers, vulcanizing and heating solutions. ; Can be used as spray for precise cleaning of small areas. | V8: Solvant de nettoyage pour éliminer la graisse et la saleté du caoutchouc afin de fournir un environnement propre pour une adhérence solide ; Pour une utilisation universelle avec des systèmes adhésifs sans CHC, des apprêts, des solutions de vulcanisation et de chauffage. ; Peut être utilisé en spray pour un nettoyage précis de petites surfaces. | W8: CHC-vrij; Gevaarlijke goederen: Ja; Uitstekend olie- en vetoplossend vermogen; Toekomstbestendig, REACH-conform; Zuinig in verbruik; T-REX-reinigingsvloeistoffen kunnen universeel worden gebruikt om olie en vet van oppervlakken te verwijderen en gebruikte borstels te reinigen (d.w.z. CHC-vrije lijmsystemen, primers, vulkanisatie- en verwarmingsoplossingen) | X8: CKW-frei ; Gefahrgut: Ja ; Hervorragend öl- und fettlösend ; Zukunftssicher, REACH-Konformität ; Sparsam im Verbrauch; T-REX Reinigungsflüssigkeiten sind universell einsetzbar zur Entfernung von Öl und Fett auf Oberflächen und zur Reinigung gebrauchter Bürsten (z. B. CKW-freie Klebstoffsysteme, Grundierungen, Vulkanisier- und Heizlösungen) | Y8: CHC-free ; Dangerous goods: Yes ; Excellent oil and grease-dissolving ; Future-proof, REACH compliance ; Economic in consumption ; T-REX cleaning fluids can be universally used to remove oil and grease from surfaces and to clean used brushes (i.e. CHC-free adhesive systems, primers, vulcanizing and heating solutions) | Z8: Sans CHC ; Marchandises dangereuses : Oui ; Excellent dissolvant d'huile et de graisse ; À l'épreuve du temps, conformité REACH ; Economique en consommation ; Les liquides de nettoyage T-REX peuvent être utilisés universellement pour éliminer l'huile et la graisse des surfaces et pour nettoyer les pinceaux usagés (c'est-à-dire les systèmes adhésifs sans CHC, les apprêts, les solutions de vulcanisation et de chauffage) | AE8: 5061982DE ; 5148730DE ; 5148760DE ; 5148770DE | AF8: 5061984DE-1 | AG8: 081 | AH8: 089 | AI8: 041 | AJ8: Reinigungsmittel
A9: 5141490DE | B9: T-Rex Vulc B 200 ltr | C9: 1.984,000 | D9: 37, Tip Top | E9: 12022, REMA TIP TOP AG | F9: Actief | G9: 1.667,930 | H9: 2990 | I9: 06_Vulcanization Materials | J9: 06-03_T-Rex Glue for Cold Vulcanization | K9: T-REX Vulc. B Vat | L9: T-REX Vulc. B Fass | M9: T-REX Vulc. B Barrel | N9: T-REX Vulc. B Fut | O9: Vat 190 kg | P9: Fass 190 kg | Q9: Barrel 190 kg | R9: Fut 190 kg | S9: Koud lassen en repareren van transportbanden met weefselversterkingen; Verlijmen van rubberen onderdelen en voeringen; Verlijmen van elastomeerkappen voor aandrijftrommels | T9: Kaltverbindungen und Reparatur von Fördergurten mit Gewebeverstärkungen; Kleben von Gummiteilen und Auskleidungen; Kleben von Elastomer-Leggings für Antriebstrommeln | U9: Cold splicing and repairs of coveyor belts with fabric reinforcements ; Bonding of rubber components and linings ; Bonding of elastomer laggings for drive pulleys | V9: Jonction et réparation à froid de bandes transporteuses avec renforts en tissu ; Collage de composants en caoutchouc et de revêtements ; Collage de jambières élastomères pour poulies motrices | W9: CHC-vrij; Gevaarlijke goederen: Ja; Uitstekende initiële hechtsterkte; Hoge dynamische draagkracht; Banden met hoge weerstand; Universeel inzetbaar op vele materialen; Toekomstbestendig, REACH-conform; Uitstekende hechting; Bewezen productkwaliteit; Eenvoudig aan te brengen; Zuinig in verbruik; Vult T-REX-slijtagebeschermings- en reparatiesystemen aan met CN-bindingslaag | X9: CKW-frei ; Gefahrgut: Ja ; Hervorragende Anfangshaftung; Hohe dynamische Belastbarkeit ; Hochfeste Bindungen ; Universell einsetzbar auf vielen Materialien; Zukunftssicher, REACH-Konformität ; Hervorragende Haftung; Bewährte Produktqualität; Einfach anzuwenden ; Sparsam im Verbrauch; Ergänzt T-REX Verschleißschutz- und Reparatursysteme mit CN-Haftschicht | Y9: CHC-free ; Dangerous goods: Yes ; Outstanding initial bond strength ; High dynamic load rating ; High-strength bonds ; Can be universally used on many materials ; Future-proof, REACH compliance ; Excellent adhesion ; Proven product quality ; Easy to apply ; Economic in consumption ; Complements T-REX wear protection and repair systems with CN bonding layer | Z9: Sans CHC ; Marchandises dangereuses : Oui ; Force de liaison initiale exceptionnelle ; Capacité de charge dynamique élevée ; Liaisons à haute résistance ; Peut être utilisé universellement sur de nombreux matériaux ; À l'épreuve du temps, conformité REACH ; Excellente adhérence ; Qualité de produit éprouvée ; Facile à appliquer ; Economique en consommation ; Complète les systèmes de protection contre l'usure et de réparation T-REX avec une couche de liaison CN | AE9: 5148760DE ; 5148770DE ; 5148730DE ; 5061984DE | AF9: 5141490DE-1 | AG9: 081 | AH9: 089 | AI9: 082 | AJ9: WTS & WTH 2004
A10: 5148730DE | B10: T-Rex Primer A - 750 g | C10: 0,000 | D10: 37, Tip Top | E10: 12022, REMA TIP TOP AG | F10: Actief | G10: 20,810 | H10: 32.5 | I10: 06_Vulcanization Materials | J10: 06-02_T-Rex Primer | K10: T-REX Primer | L10: T-REX Primer / Grundierung | M10: T-REX Primer | N10: T-REX Primer / Apprêt | O10: Blik 0,75 Kg | P10: Kanne 0,75 Kg | Q10: Can 0,75 Kg | R10: Pot 0,75 Kg | W10: CHC-vrij; Gevaarlijke goederen: Ja; Kleur: grijs ; Toekomstbestendig, REACH-conform; Zuinig in verbruik; Uitstekende hechting in combinatie met T-REX Vulc. B ; Korte droogtijd; Extra tijdelijke bescherming tegen atmosferische corrosie (vochtigheid) | X10: CKW-frei ; Gefahrgut: Ja ; Farbe: Grau; Zukunftssicher, REACH-Konformität ; Sparsam im Verbrauch; Hervorragende Haftung in Kombination mit T-REX Vulc. B ; Kurze Trocknungszeit ; Zusätzlicher temporärer Schutz gegen atmosphärische Korrosion (Feuchtigkeit) | Y10: CHC-free ; Dangerous goods: Yes ; Colour: Gray ; Future-proof, REACH compliance ; Economic in consumption ; Excellent adhesion in combination with T-REX Vulc. B ; Short drying time ; Additional temporary protection for atmospheric corrosion (humidity) | Z10: Sans CHC ; Marchandises dangereuses : Oui ; Couleur : Gris ; À l'épreuve du temps, conformité REACH ; Economique en consommation ; Excellente adhérence en combinaison avec T-REX Vulc. B ; Temps de séchage court ; Protection temporaire supplémentaire contre la corrosion atmosphérique (humidité) | AA10: Primer wordt gebruikt voor het voorbehandelen van metalen oppervlakken van elastomeer-metaalverbindingen voorafgaand aan rubber-metaalverbindingen met hoge dynamische en statische belastingen | AB10: Primer dienen zur Vorbehandlung von Metalloberflächen von Elastomer-Metall-Verbindungen vor Gummi-Metall-Verbindungen mit hohen dynamischen und statischen Belastungen | AC10: Primer are used to pretreat metal surfaces of elastomer-metal bonds prior to rubber-metal bonding with high dynamic and static loads | AD10: Les apprêts sont utilisés pour prétraiter les surfaces métalliques des liaisons élastomère-métal avant la liaison caoutchouc-métal avec des charges dynamiques et statiques élevées | AE10: 5148760DE ; 5148770DE- ; 5061984DE | AF10: 5148730DE-1 | AG10: 081 | AH10: 089 | AI10: 051 | AJ10: Primer
A11: 5148760DE | B11: T-Rex Vulc B - 700 g | C11: 0,000 | D11: 37, Tip Top | E11: 12022, REMA TIP TOP AG | F11: Actief | G11: 8,740 | H11: 16.1 | I11: 06_Vulcanization Materials | J11: 06-03_T-Rex Glue for Cold Vulcanization | K11: T-REX Vulc. B | L11: T-REX Vulc. B | M11: T-REX Vulc. B | N11: T-REX Vulc. B | O11: Blik 0,7 Kg | P11: Kanne 0,7 Kg | Q11: Can 0,7 Kg | R11: Pot 0,7 Kg | S11: Koud lassen en repareren van transportbanden met weefselversterkingen; Verlijmen van rubberen onderdelen en voeringen; Verlijmen van elastomeerkappen voor aandrijftrommels | T11: Kaltverbindungen und Reparatur von Fördergurten mit Gewebeverstärkungen; Kleben von Gummiteilen und Auskleidungen; Kleben von Elastomer-Leggings für Antriebstrommeln | U11: Cold splicing and repairs of coveyor belts with fabric reinforcements ; Bonding of rubber components and linings ; Bonding of elastomer laggings for drive pulleys | V11: Jonction et réparation à froid de bandes transporteuses avec renforts en tissu ; Collage de composants en caoutchouc et de revêtements ; Collage de jambières élastomères pour poulies motrices | W11: CHC-vrij; Gevaarlijke goederen: Ja; Uitstekende initiële hechtsterkte; Hoge dynamische draagkracht; Banden met hoge weerstand; Universeel inzetbaar op vele materialen; Toekomstbestendig, REACH-conform; Uitstekende hechting; Bewezen productkwaliteit; Eenvoudig aan te brengen; Zuinig in verbruik; Vult T-REX-slijtagebeschermings- en reparatiesystemen aan met CN-bindingslaag | X11: CKW-frei ; Gefahrgut: Ja ; Hervorragende Anfangshaftung; Hohe dynamische Belastbarkeit ; Hochfeste Bindungen ; Universell einsetzbar auf vielen Materialien; Zukunftssicher, REACH-Konformität ; Hervorragende Haftung; Bewährte Produktqualität; Einfach anzuwenden ; Sparsam im Verbrauch; Ergänzt T-REX Verschleißschutz- und Reparatursysteme mit CN-Haftschicht | Y11: CHC-free ; Dangerous goods: Yes ; Outstanding initial bond strength ; High dynamic load rating ; High-strength bonds ; Can be universally used on many materials ; Future-proof, REACH compliance ; Excellent adhesion ; Proven product quality ; Easy to apply ; Economic in consumption ; Complements T-REX wear protection and repair systems with CN bonding layer | Z11: Sans CHC ; Marchandises dangereuses : Oui ; Force de liaison initiale exceptionnelle ; Capacité de charge dynamique élevée ; Liaisons à haute résistance ; Peut être utilisé universellement sur de nombreux matériaux ; À l'épreuve du temps, conformité REACH ; Excellente adhérence ; Qualité de produit éprouvée ; Facile à appliquer ; Economique en consommation ; Complète les systèmes de protection contre l'usure et de réparation T-REX avec une couche de liaison CN | AE11: 5141490DE ; 5148770DE ; 5148730DE ; 5061984DE | AF11: 5148760DE-1 ; 5148760DE-2 | AG11: 081 | AH11: 089 | AI11: 082 | AJ11: WTS & WTH 2004
A12: 5148770DE | B12: T-Rex Vulc B-H - 30 g | C12: 0,000 | D12: 37, Tip Top | E12: 12022, REMA TIP TOP AG | F12: Actief | G12: 2,180 | H12: 4.2 | I12: 06_Vulcanization Materials | J12: 06-03_T-Rex Glue for Cold Vulcanization | K12: T-REX Vulc . B Verharder | L12: T-REX Vulc. B Härter | M12: T-REX Vulc. B Hardener | N12: T-REX Vulc. B Durcisseur | O12: Flesje 30 Gr | P12: Flasche 30 Gr | Q12: Bottle 30 Gr | R12: Flacons 30 Gr | S12: Koud lassen en repareren van transportbanden met weefselversterkingen; Verlijmen van rubberen onderdelen en voeringen; Verlijmen van elastomeerkappen voor aandrijftrommels | T12: Kaltverbindungen und Reparatur von Fördergurten mit Gewebeverstärkungen; Kleben von Gummiteilen und Auskleidungen; Kleben von Elastomer-Leggings für Antriebstrommeln | U12: Cold splicing and repairs of coveyor belts with fabric reinforcements ; Bonding of rubber components and linings ; Bonding of elastomer laggings for drive pulleys | V12: Jonction et réparation à froid de bandes transporteuses avec renforts en tissu ; Collage de composants en caoutchouc et de revêtements ; Collage de jambières élastomères pour poulies motrices | W12: CHC-vrij; Gevaarlijke goederen: Ja; Uitstekende initiële hechtsterkte; Hoge dynamische draagkracht; Banden met hoge weerstand; Universeel inzetbaar op vele materialen; Toekomstbestendig, REACH-conform; Uitstekende hechting; Bewezen productkwaliteit; Eenvoudig aan te brengen; Zuinig in verbruik; Vult T-REX-slijtagebeschermings- en reparatiesystemen aan met CN-bindingslaag | X12: CKW-frei ; Gefahrgut: Ja ; Hervorragende Anfangshaftung; Hohe dynamische Tragzahl; Hochfeste Bindungen ; Universell einsetzbar auf vielen Materialien; Zukunftssicher, REACH-Konformität ; Hervorragende Haftung; Bewährte Produktqualität; Einfach anzuwenden ; Sparsam im Verbrauch; Ergänzt T-REX Verschleißschutz- und Reparatursysteme mit CN-Haftschicht | Y12: CHC-free ; Dangerous goods: Yes ; Outstanding initial bond strength ; High dynamic load rating ; High-strength bonds ; Can be universally used on many materials ; Future-proof, REACH compliance ; Excellent adhesion ; Proven product quality ; Easy to apply ; Economic in consumption ; Complements T-REX wear protection and repair systems with CN bonding layer | Z12: Sans CHC ; Marchandises dangereuses : Oui ; Force de liaison initiale exceptionnelle ; Capacité de charge dynamique élevée ; Liaisons à haute résistance ; Peut être utilisé universellement sur de nombreux matériaux ; À l'épreuve du temps, conformité REACH ; Excellente adhérence ; Qualité de produit éprouvée ; Facile à appliquer ; Economique en consommation ; Complète les systèmes de protection contre l'usure et de réparation T-REX avec une couche de liaison CN | AA12: Voor lijm T-REX Vulc. B | AB12: Für Kleber T-REX Vulc. B | AC12: For glue T-REX Vulc. B | AD12: Pour colle T-REX Vulc. B | AE12: 5148760DE ; 5141490DE ; 5061984DE ; 5148730DE | AF12: 5148770DE-1 ; 5148770DE-2 | AG12: 081 | AH12: 089 | AI12: 082 | AJ12: WTS & WTH 2004
A13: 5210222DE | B13: REMALINE 70/CN 25X2000 | C13: 0,000 | D13: 37, Tip Top | E13: 12022, REMA TIP TOP AG | F13: Actief | G13: 10,000 | I13: x | J13: x | AG13: 081
A14: 5210407DE | B14: REMA PERFORMANCE GRIP 70/CN (8x6) 10X2000 | C14: 0,000 | D14: 37, Tip Top | E14: 12022, REMA TIP TOP AG | F14: Actief | G14: 10,000 | I14: x | J14: x | AG14: 081
A15: 5210412DE | B15: REMA PERFORMANCE GRIP 70/CN (8x6) 15X2000 | C15: 0,000 | D15: 37, Tip Top | E15: 12022, REMA TIP TOP AG | F15: Actief | G15: 10,000 | I15: x | J15: x | AG15: 081
A16: 5210417DE | B16: REMA PERFORMANCE GRIP 70/CN (10x8) 15X2000 | C16: 0,000 | D16: 37, Tip Top | E16: 12022, REMA TIP TOP AG | F16: Actief | G16: 10,000 | I16: x | J16: x | AG16: 081
A17: 5210422DE | B17: REMA PERFORMANCE GRIP 70/CN (10x8) 15X2000 | C17: 0,000 | D17: 37, Tip Top | E17: 12022, REMA TIP TOP AG | F17: Actief | G17: 10,000 | I17: x | J17: x | AG17: 081
A18: 5243331DE | B18: DX LINE BL STANDARD 60 Shore T | C18: 0,000 | D18: 37, Tip Top | E18: 12022, REMA TIP TOP AG | F18: Actief | G18: 10,000 | I18: x | J18: x | AG18: 081
A19: 5247440DE | B19: DX SKIRT STANDARD 60 Shore T2 | C19: 0,000 | D19: 37, Tip Top | E19: 12022, REMA TIP TOP AG | F19: Actief | G19: 10,000 | I19: x | J19: x | AG19: 081
A20: 5248120CH | B20: T-Rex Repair Strip -10.000x150x3,2 mm | C20: 0,000 | D20: 37, Tip Top | E20: 12021, REMA TIP TOP (Tianjin) Rubber Technology Co., Ltd. | F20: Actief | G20: 10,000 | H20: 96.2 | I20: 07_Repair Material | J20: 07-05_T-Rex Repair Strips | K20: T-REX Reparatie strip 150mm ; Zonder weefselinlage | L20: T-REX Reparaturband 150mm ; Ohne Gewebeeinlage | M20: T-REX Repair strip 150mm ; Without fabric reinforced | N20: T-REX Bande de réparation 150mm ; Sans pli renforcé | O20: Nr. 2 ; Afmeting: 10.000 x 150 mm ; Dikte: 3,2 mm ; Zonder weefselinlage ; Kleur: Zwart | P20: Nr. 2 ; Abmessung: 10.000 x 150 mm ; Starke: 3,2 mm ; Ohne Gewebeeinlage ; Farbe: Schwarz | Q20: Nr. 2 ; Dimensions: 10.000 x 150 mm ; Thickness: 3,2 mm ; Without fabric ; Colour: Black | R20: Nr. 2 ; Dimensions : 10.000 x 150 mm ; Epaisseur : 3,2 mm ; Sans pli ; Couleur : Noir | AA20: Voor het repareren van dekplaatbeschadigingen in de looprichting van de band; | AB20: Für die Reparatur von Deckplattenschäden in Gurtlaufrichtung ; | AC20: For repairing cover plate damage in the direction of travel of the belt; | AD20: Pour réparer les dommages de la plaque de couverture dans le sens de déplacement de la bande ; | AE20: 5317739CH ; 5315748CH ; 5061984DE ; 5148760DE | AG20: 081 | AH20: 088 | AI20: 024 | AJ20: Reparaturband
A21: 5290177DE | B21: ABB-45 8x2000 | C21: 0,000 | D21: 1, Rubber transportbanden | E21: 12028, REMA TIP TOP DBP B.V. | F21: Actief | G21: 10,000 | I21: x | J21: x | AG21: 081
A22: 5290420DE | B22: REMALINE 40B ROOD 6X2000 | C22: 0,000 | D22: 37, Tip Top | E22: 12022, REMA TIP TOP AG | F22: Actief | G22: 10,010 | I22: x | J22: x | AG22: 081
A23: 5290451DE | B23: REMASKIRT 50/65 12X2000 | C23: 0,000 | D23: 37, Tip Top | E23: 12022, REMA TIP TOP AG | F23: Actief | G23: 5,000 | I23: x | J23: x | AG23: 081
A24: 5291474DE | B24: NK-ROT 12 X 2000 | C24: 0,000 | D24: 1, Rubber transportbanden | E24: 12028, REMA TIP TOP DBP B.V. | F24: Actief | G24: 10,000 | I24: x | J24: x | AG24: 081
A25: 5291522 11DE | B25: NK-ROT 6X2000X10000 | C25: 0,000 | D25: 37, Tip Top | E25: 12022, REMA TIP TOP AG | F25: Actief | G25: 10,010 | I25: x | J25: x | AG25: 081
A26: 5305514CH | B26: T-Rex Repair Patch Size 1 with fabric, 160 x 130 x 3,8 mm | C26: 0,000 | D26: 37, Tip Top | E26: 12021, REMA TIP TOP (Tianjin) Rubber Technology Co., Ltd. | F26: Actief | G26: 1,750 | H26: 3 | I26: 07_Repair Material | J26: 07-04_T-Rex Repair Patches | K26: T-REX Reparatie pleister 160 x 130 mm ; Met weefselinlage | L26: T-REX Reparatur Flicken 160 x 130mm ; Mit Gewebeeinlage | M26: T-REX Repair Patch 160 x 130mm ; With fabric reinforced | N26: T-Rex Rustine avec pli numéro 1, 160 x 130mm | O26: Nr. 1 ; Afmeting: 160 x 130 mm ; Dikte: 3,8 mm ; Met weefselinlage EP 160 ; Kleur: Zwart | P26: Nr. 1 ; Abmessung: 160 x 130 mm ; Starke: 3,8 mm ; Mit Gewebeeinlage EP 160 ; Farbe: Schwarz | Q26: Nr. 1 ; Dimensions: 160 x 130 mm ; Thickness: 3,8 mm ; With fabric reinforced EP 160 ; Colour: Black | R26: Nr. 1 ; Dimensions : 160 x 130 mm ; Epaisseur : 3,8 mm ; Avec tissu renforcé EP 160 ; Couleur : Noir | S26: stk. T-Rex Reparatiepleister maat 1 - met weefsel - afmeting 160 x 130 x 3,8 mm (02684482) | AA26: Voor het repareren van banden | AB26: Für die Reparatur von Durchschlägen ; | AC26: For repairing punctures | AD26: Pour réparer les crevaisons | AE26: 5307512CH ; FOURTHANE-RED-00130002FT ; 5061984DE ; 5148760DE | AF26: 5305514CH-1; 5305514CH-2 | AG26: 081 | AH26: 088 | AI26: 021 | AJ26: Reparaturflicken
A27: 5305521CH | B27: T-Rex Repair Patch Size 2 with fabric, 260 x 200 x 3,8 mm | C27: 0,000 | D27: 37, Tip Top | E27: 12021, REMA TIP TOP (Tianjin) Rubber Technology Co., Ltd. | F27: Actief | G27: 2,360 | H27: 4.15 | I27: 07_Repair Material | J27: 07-04_T-Rex Repair Patches | K27: T-REX Reparatie pleister 260 x 200 mm ; Met weefselinlage | L27: T-REX Reparatur Flicken 260 x 200mm ; Mit Gewebeeinlage | M27: T-REX Repair Patch 260 x 200mm ; With fabric reinforced | N27: T-Rex Rustine avec pli numéro 2, 260 x 200mm | O27: Nr. 2 ; Afmeting: 260 x 200 mm ; Dikte: 3,8 mm ; Met weefselinlage EP 160 ; Kleur: Zwart | P27: Nr. 2 ; Abmessung: 260 x 200 mm ; Starke: 3,8 mm ; Mit Gewebeeinlage EP 160 ; Farbe: Schwarz | Q27: Nr. 2 ; Dimensions: 260 x 200 mm ; Thickness: 3,8 mm ; With fabric reinforced EP 160 ; Colour: Black | R27: Nr. 2 ; Dimensions : 260 x 200 mm ; Epaisseur : 3,8 mm ; Avec tissu renforcé EP 160 ; Couleur : Noir | S27: stk. T-Rex Reparatiepleister maat 2 - met weefsel - afmeting 260 x 200 x 3,8 mm (02684482) | AA27: Voor het repareren van banden | AB27: Für die Reparatur von Durchschlägen ; | AC27: For repairing punctures | AD27: Pour réparer les crevaisons | AE27: 5307529CH ; FOURTHANE-RED-00130002FT ; 5061984DE ; 5148760DE | AF27: 5305521CH-1; 5305521CH-2 | AG27: 081 | AH27: 088 | AI27: 021 | AJ27: Reparaturflicken
A28: 5305538CH | B28: T-Rex Repair Patch Size 3 with fabric, 360 x 270 x 3,8 mm | C28: 0,000 | D28: 37, Tip Top | E28: 12021, REMA TIP TOP (Tianjin) Rubber Technology Co., Ltd. | F28: Actief | G28: 4,130 | H28: 7.25 | I28: 07_Repair Material | J28: 07-04_T-Rex Repair Patches | K28: T-REX Reparatie pleister 360 x 270 mm ; Met weefselinlage | L28: T-REX Reparatur Flicken 360 x 270mm ; Mit Gewebeeinlage | M28: T-REX Repair Patch 360 x 270mm ; With fabric reinforced | N28: T-Rex Rustine avec pli numéro 3, 360 x 270mm | O28: Nr. 3 ; Afmeting: 360 x 270 mm ; Dikte: 3,8 mm ; Met weefselinlage EP 160 ; Kleur: Zwart | P28: Nr. 3 ; Abmessung: 360 x 270 mm ; Starke: 3,8 mm ; Mit Gewebeeinlage EP 160 ; Farbe: Schwarz | Q28: Nr. 3 ; Dimensions: 360 x 270 mm ; Thickness: 3,8 mm ; With fabric reinforced EP 160 ; Colour: Black | R28: Nr. 3 ; Dimensions : 360 x 270 mm ; Epaisseur : 3,8 mm ; Avec tissu renforcé EP 160 ; Couleur : Noir | S28: stk. T-Rex Reparatiepleister maat 3 - met weefsel - afmeting 360 x 270 x 3,8 mm (02684482) | AA28: Voor het repareren van banden | AB28: Für die Reparatur von Durchschlägen ; | AC28: For repairing punctures | AD28: Pour réparer les crevaisons | AE28: 5307536CH ; FOURTHANE-RED-00130002FT ; 5061984DE ; 5148760DE | AF28: 5305538CH-1; 5305538CH-2 | AG28: 081 | AH28: 088 | AI28: 021 | AJ28: Reparaturflicken
A29: 5305540CH | B29: T-Rex Repair Patch Size 4 with fabric, 470 x 360 x 4,4 mm | C29: 0,000 | D29: 37, Tip Top | E29: 12021, REMA TIP TOP (Tianjin) Rubber Technology Co., Ltd. | F29: Actief | G29: 6,230 | H29: 10.75 | I29: 07_Repair Material | J29: 07-04_T-Rex Repair Patches | K29: T-REX Reparatie pleister 470 x 360 mm ; Met weefselinlage | L29: T-REX Reparatur Flicken 470 x 360mm ; Mit Gewebeeinlage | M29: T-REX Repair Patch 470 x 360mm ; With fabric reinforced | N29: T-Rex Rustine avec pli numéro 4, 470 x 360mm | O29: Nr. 4 ; Afmeting: 470 x 360 mm ; Dikte: 4,4 mm ; Met weefselinlage EP 160 ; Kleur: Zwart | P29: Nr. 4 ; Abmessung: 470 x 360 mm ; Starke: 4,4 mm ; Mit Gewebeeinlage EP 160 ; Farbe: Schwarz | Q29: Nr. 4 ; Dimensions: 460 x 360 mm ; Thickness: 4,4 mm ; With fabric reinforced EP 160 ; Colour: Black | R29: Nr. 4 ; Dimensions : 460 x 360 mm ; Epaisseur : 4,4 mm ; Avec tissu renforcé EP 160 ; Couleur : Noir | S29: stk. T-Rex Reparatiepleister maat 4 - met weefsel - afmeting 470 x 360 x 4,4 mm (02684482) | AA29: Voor het repareren van banden | AB29: Für die Reparatur von Durchschlägen ; | AC29: For repairing punctures | AD29: Pour réparer les crevaisons | AE29: 5307536CH ; FOURTHANE-RED-00130002FT ; 5061984DE ; 5148760DE | AF29: 5305540CH-1; 5305540CH-2 | AG29: 081 | AH29: 088 | AI29: 021 | AJ29: Reparaturflicken
A30: 5307512CH | B30: T-Rex Repair Patch Size 1, 160 x 130 x 2,4 mm | C30: 1,440 | D30: 37, Tip Top | E30: 12021, REMA TIP TOP (Tianjin) Rubber Technology Co., Ltd. | F30: Actief | G30: 1,280 | H30: 2.4 | I30: 07_Repair Material | J30: 07-04_T-Rex Repair Patches | K30: T-REX Reparatie pleister 160 x 130 mm ; Zonder weefselinlage | L30: T-REX Reparatur Flicken 160 x 130mm ; Ohne Gewebeeinlage | M30: T-REX Repair Patch 160 x 130mm ; Without fabric reinforced | N30: T-Rex Rustine sans pli numéro 1,160 x 130mm | O30: Nr. 1 ; Afmeting: 160 x 130 mm ; Dikte: 2,2 mm ; Zonder weefselinlage ; Kleur: Zwart | P30: Nr. 1 ; Abmessung: 160 x 130 mm ; Starke: 3,8 mm ; Ohne Gewebeeinlage ; Farbe: Schwarz | Q30: Nr. 1 ; Dimensions: 160 x 130 mm ; Thickness: 2,4 mm ; Without fabric ; Colour: Black | R30: Nr. 1 ; Dimensions : 160 x 130 mm ; Epaisseur : 2,4 mm ; Sans tissu ; Couleur : Noir | S30: stk. T-Rex Reparatiepleister maat 1 - zonder weefsel - afmeting 160 x 130 x 2,4 mm (02684482) | AA30: Voor het repareren van dekschade | AB30: Für die Reparatur von Deckplattenschäden ; | AC30: For repairing cover damage | AD30: Pour réparer les dommages au pont | AE30: 5305514CH ; FOURTHANE-RED-00130002FT ; 5061984DE ; 5148760DE | AF30: 5307512CH-2; 5307512CH-3 | AG30: 081 | AH30: 088 | AI30: 021 | AJ30: Reparaturflicken
A31: 5307529CH | B31: T-Rex Repair Patch Size 2, 260 x 200 x 2,4 mm | C31: 2,160 | D31: 37, Tip Top | E31: 12021, REMA TIP TOP (Tianjin) Rubber Technology Co., Ltd. | F31: Actief | G31: 1,800 | H31: 3.1 | I31: 07_Repair Material | J31: 07-04_T-Rex Repair Patches | K31: T-REX Reparatie pleister 260 x 200 mm ; Zonder weefselinlage | L31: T-REX Reparatur Flicken 260 x 2000mm ; Ohne Gewebeeinlage | M31: T-REX Repair Patch 260 x 200mm ; Without fabric reinforced | N31: T-Rex Rustine sans pli numéro 2, 260 x 200mm | O31: Nr. 2; Afmeting: 260 x 200 mm ; Dikte: 2,4 mm ; Zonder weefselinlage ; Kleur: Zwart | P31: Nr. 2 ; Abmessung: 260 x 200 mm ; Starke: 2,4 mm ; Ohne Gewebeeinlage ; Farbe: Schwarz | Q31: Nr. 2 ; Dimensions: 260 x 200 mm ; Thickness: 2,4 mm ; Without fabric ; Colour: Black | R31: Nr. 2 ; Dimensions : 260 x 200 mm ; Epaisseur : 2,4 mm ; Sans tissu ; Couleur : Noir | S31: stk. T-Rex Reparatiepleister maat 2 - zonder weefsel - afmeting 260 x 200 x 2,4 mm (02684482) | AA31: Voor het repareren van dekschade | AB31: Für die Reparatur von Deckplattenschäden ; | AC31: For repairing cover damage | AD31: Pour réparer les dommages au pont | AE31: 5305521CH ; FOURTHANE-RED-00130002FT ; 5061984DE ; 5148760DE | AF31: 5307529CH-2; 5307529CH-3 | AG31: 081 | AH31: 088 | AI31: 021 | AJ31: Reparaturflicken
A32: 5307536CH | B32: T-Rex Repair Patch Size 3, 360 x 270 x 2,4 mm | C32: 0,000 | D32: 37, Tip Top | E32: 12021, REMA TIP TOP (Tianjin) Rubber Technology Co., Ltd. | F32: Actief | G32: 2,720 | H32: 5.15 | I32: 07_Repair Material | J32: 07-04_T-Rex Repair Patches | K32: T-REX Reparatie pleister 360 x 270 mm ; Zonder weefselinlage | L32: T-REX Reparatur Flicken 360 x 270mm ; Ohne Gewebeeinlage | M32: T-REX Repair Patch 360 x 270mm ; Without fabric reinforced | N32: T-Rex Rustine sans pli numéro 3, 360 x 270mm | O32: Nr. 3 ; Afmeting: 360 x 270 mm ; Dikte: 2,4 mm ; Zonder weefselinlage ; Kleur: Zwart | P32: Nr. 3 ; Abmessung: 360 x 270 mm ; Starke: 2,4 mm ; Ohne Gewebeeinlage ; Farbe: Schwarz | Q32: Nr. 3 ; Dimensions: 360 x 270 mm ; Thickness: 2,4 mm ; Without fabric ; Colour: Black | R32: Nr. 3 ; Dimensions : 360 x 270 mm ; Epaisseur : 2,4 mm ; Sans tissu ; Couleur : Noir | S32: stk. T-Rex Reparatiepleister maat 3 - zonder weefsel - afmeting 360 x 270 x 2,4 mm (02684482) | AA32: Voor het repareren van dekschade | AB32: Für die Reparatur von Deckplattenschäden ; | AC32: For repairing cover damage | AD32: Pour réparer les dommages au pont | AE32: 5305538CH ; FOURTHANE-RED-00130002FT ; 5061984DE ; 5148760DE | AF32: 5307536CH-2; 5307536CH-3 | AG32: 081 | AH32: 088 | AI32: 021 | AJ32: Reparaturflicken
A33: 5315731CH | B33: T-Rex Repair Strip with fabric Nr 1 -10.000x100x3,6 mm | C33: 0,000 | D33: 37, Tip Top | E33: 12021, REMA TIP TOP (Tianjin) Rubber Technology Co., Ltd. | F33: Actief | G33: 51,380 | H33: 83.25 | I33: 07_Repair Material | J33: 07-05_T-Rex Repair Strips | K33: T-REX Reparatie strip 100mm ; Met weefselinlage | L33: T-REX Reparaturband 100mm ; Mit Gewebeeinlage | M33: T-REX Repair strip 100mm ; With fabric reinforced | N33: T-REX Bande de réparation 100mm ; Avec pli renforcé | O33: Nr. 1 ; Afmeting: 10.000 x 100 mm ; Dikte: 3,6 mm ; Met weefselinlage EP 160 ; Kleur: Zwart | P33: Nr. 1 ; Abmessung: 10.000 x 100 mm ; Starke: 3,6 mm ; Mit Gewebeeinlage EP 160 ; Farbe: Schwarz | Q33: Nr. 1 ; Dimensions: 10.000 x 100 mm ; Thickness: 3,6 mm ; With fabric EP160 ; Colour: Black | R33: Nr. 1 ; Dimensions : 10.000 x 100 mm ; Epaisseur : 3,6 mm ; Avec pli EP160 ; Couleur : Noir | AA33: Voor het repareren van lengtescheuren in transportbanden van textiel en staalkoord; | AB33: Für die Reparatur von Längsrissen in Gewebe- und Stahlseilfördergurten ; | AC33: For repairing longitudinal tears in fabric and steel cord conveyor belts; | AD33: Pour réparer les déchirures longitudinales des bandes transporteuses en tissu et en câble d'acier | AE33: 5317739CH ; 5315748CH ; 5061984DE ; 5148760DE | AG33: 081 | AH33: 088 | AI33: 024 | AJ33: Reparaturband
A34: 5315748CH | B34: T-Rex Repair Strip with fabric Nr 2 -10.000x150x4,6 mm | C34: 0,000 | D34: 37, Tip Top | E34: 12021, REMA TIP TOP (Tianjin) Rubber Technology Co., Ltd. | F34: Actief | G34: 84,840 | H34: 147.9 | I34: 07_Repair Material | J34: 07-05_T-Rex Repair Strips | K34: T-REX Reparatie strip 150mm ; Met weefselinlage | L34: T-REX Reparaturband 150mm ; Mit Gewebeeinlage | M34: T-REX Repair strip 150mm ; With fabric reinforced | N34: T-REX Bande de réparation 150mm ; Avec pli renforcé | O34: Nr. 2 ; Afmeting: 10.000 x 150 mm ; Dikte: 4,6 mm ; Met weefselinlage EP 160 ; Kleur: Zwart | P34: Nr. 2 ; Abmessung: 10.000 x 150 mm ; Starke: 4,6 mm ; Mit Gewebeeinlage EP 160 ; Farbe: Schwarz | Q34: Nr. 2 ; Dimensions: 10.000 x 150 mm ; Thickness: 4,6 mm ; With fabric EP160 ; Colour: Black | R34: Nr. 2 ; Dimensions : 10.000 x 150 mm ; Epaisseur : 4,6 mm ; Avec pli EP160 ; Couleur : Noir | AA34: Voor het repareren van lengtescheuren in transportbanden van textiel en staalkoord; | AB34: Für die Reparatur von Längsrissen in Gewebe- und Stahlseilfördergurten ; | AC34: For repairing longitudinal tears in fabric and steel cord conveyor belts; | AD34: Pour réparer les déchirures longitudinales des bandes transporteuses en tissu et en câble d'acier | AE34: 5315731CH ; 5315748CH ; 5061984DE ; 5148760DE | AG34: 081 | AH34: 088 | AI34: 024 | AJ34: Reparaturband
A35: 5315755CH | B35: T-Rex Repair Strip with fabric Nr 3 -10.000x220x4,6 mm | C35: 0,000 | D35: 37, Tip Top | E35: 12021, REMA TIP TOP (Tianjin) Rubber Technology Co., Ltd. | F35: Actief | G35: 130,770 | H35: 238 | I35: 07_Repair Material | J35: 07-05_T-Rex Repair Strips | K35: T-REX Reparatie strip 220mm ; Met weefselinlage | L35: T-REX Reparaturband 220mm ; Mit Gewebeeinlage | M35: T-REX Repair strip 220mm ; With fabric reinforced | N35: T-REX Bande de réparation 220mm ; Avec pli renforcé | O35: Nr. 3 ; Afmeting: 10.000 x 220 mm ; Dikte: 4,6 mm ; Met weefselinlage EP 160 ; Kleur: Zwart | P35: Nr. 3 ; Abmessung: 10.000 x 220 mm ; Starke: 4,6 mm ; Mit Gewebeeinlage EP 160 ; Farbe: Schwarz | Q35: Nr. 3 ; Dimensions: 10.000 x 100 mm ; Thickness: 4,6 mm ; With fabric EP160 ; Colour: Black | R35: Nr. 3 ; Dimensions : 10.000 x 100 mm ; Epaisseur : 4,6 mm ; Avec pli EP160 ; Couleur : Noir | AA35: Voor het repareren van lengtescheuren in transportbanden van textiel en staalkoord; | AB35: Für die Reparatur von Längsrissen in Gewebe- und Stahlseilfördergurten ; | AC35: For repairing longitudinal tears in fabric and steel cord conveyor belts; | AD35: Pour réparer les déchirures longitudinales des bandes transporteuses en tissu et en câble d'acier | AE35: 5315748CH ; 5317752CH ; 5061984DE ; 5148760DE | AG35: 081 | AH35: 088 | AI35: 024 | AJ35: Reparaturband
A36: 5315760CH | B36: T-Rex Repair Strip with fabric Nr 4 -10.000x300x4,8 mm | C36: 0,000 | D36: 37, Tip Top | E36: 12021, REMA TIP TOP (Tianjin) Rubber Technology Co., Ltd. | F36: Actief | G36: 164,200 | H36: 271.4 | I36: 07_Repair Material | J36: 07-05_T-Rex Repair Strips | K36: T-REX Reparatie strip 300mm ; Met weefselinlage | L36: T-REX Reparaturband 300mm ; Mit Gewebeeinlage | M36: T-REX Repair strip 300mm ; With fabric reinforced | N36: T-REX Bande de réparation 300mm ; Avec pli renforcé | O36: Nr. 4 ; Afmeting: 10.000 x 300 mm ; Dikte: 4,8 mm ; Met weefselinlage EP 160 ; Kleur: Zwart | P36: Nr. 4 ; Abmessung: 10.000 x 300 mm ; Starke: 4,8 mm ; Mit Gewebeeinlage EP 160 ; Farbe: Schwarz | Q36: Nr. 4 ; Dimensions: 10.000 x 300 mm ; Thickness: 4,8 mm ; With fabric EP160 ; Colour: Black | R36: Nr. 4 ; Dimensions : 10.000 x 300 mm ; Epaisseur : 4,8 mm ; Avec pli EP160 ; Couleur : Noir | AA36: Voor het repareren van lengtescheuren in transportbanden van textiel en staalkoord; | AB36: Für die Reparatur von Längsrissen in Gewebe- und Stahlseilfördergurten ; | AC36: For repairing longitudinal tears in fabric and steel cord conveyor belts; | AD36: Pour réparer les déchirures longitudinales des bandes transporteuses en tissu et en câble d'acier | AE36: 5315755CH ; 5317768CH ; 5061984DE ; 5148760DE | AG36: 081 | AH36: 088 | AI36: 024 | AJ36: Reparaturband
A37: 5315770CH | B37: T-Rex Repair Strip with fabric Nr 5 -10.000x400x4,8 mm | C37: 0,000 | D37: 37, Tip Top | E37: 12021, REMA TIP TOP (Tianjin) Rubber Technology Co., Ltd. | F37: Actief | G37: 214,010 | H37: 372.75 | I37: 07_Repair Material | J37: 07-05_T-Rex Repair Strips | K37: T-REX Reparatie strip 400mm ; Met weefselinlage | L37: T-REX Reparaturband 400mm ; Mit Gewebeeinlage | M37: T-REX Repair strip 400mm ; With fabric reinforced | N37: T-REX Bande de réparation 400mm ; Avec pli renforcé | O37: Nr. 5 ; Afmeting: 10.000 x 400 mm ; Dikte: 4,8 mm ; Met weefselinlage EP 160 ; Kleur: Zwart | P37: Nr. 5 ; Abmessung: 10.000 x 400 mm ; Starke: 4,8mm ; Mit Gewebeeinlage EP 160 ; Farbe: Schwarz | Q37: Nr. 5 ; Dimensions: 10.000 x 400 mm ; Thickness: 4,8 mm ; With fabric EP160 ; Colour: Black | R37: Nr. 5 ; Dimensions : 10.000 x 400 mm ; Epaisseur : 4,8 mm ; Avec pli EP160 ; Couleur : Noir | AA37: Voor het repareren van lengtescheuren in transportbanden van textiel en staalkoord; | AB37: Für die Reparatur von Längsrissen in Gewebe- und Stahlseilfördergurten ; | AC37: For repairing longitudinal tears in fabric and steel cord conveyor belts; | AD37: Pour réparer les déchirures longitudinales des bandes transporteuses en tissu et en câble d'acier | AE37: 5315760CH ; 5317768CH ; 5061984DE ; 5148760DE | AG37: 081 | AH37: 088 | AI37: 024 | AJ37: Reparaturband
A38: 5317720CH | B38: T-Rex Repair Strip Nr 00-20.000x35x1,7 mm | C38: 0,000 | D38: 37, Tip Top | E38: 12021, REMA TIP TOP (Tianjin) Rubber Technology Co., Ltd. | F38: Actief | G38: 25,360 | H38: 42.8 | I38: 07_Repair Material | J38: 07-05_T-Rex Repair Strips | K38: T-REX Reparatie strip 35mm ; Zonder weefselinlage | L38: T-REX Reparaturband 35mm ; Ohne Gewebeeinlage | M38: T-REX Repair strip 35mm ; Without fabric reinforced | N38: T-REX Bande de réparation 35mm ; Sans pli renforcé | O38: Nr. 00 ; Afmeting: 20.000 x 35 mm ; Dikte: 1,7 mm ; Zonder weefselinlage ; Kleur: Zwart | P38: Nr. 00 ; Abmessung: 20.000 x 35 mm ; Starke: 1,7 mm ; Ohne Gewebeeinlage ; Farbe: Schwarz | Q38: Nr. 00 ; Dimensions: 20.000 x 35 mm ; Thickness: 1,7 mm ; Without fabric ; Colour: Black | R38: Nr. 00 ; Dimensions : 20.000 x 35 mm ; Epaisseur : 1,7 mm ; Sans pli ; Couleur : Noir | AA38: Voor het repareren van dekplaatbeschadigingen in de looprichting van de band; | AB38: Für die Reparatur von Deckplattenschäden in Gurtlaufrichtung ; | AC38: For repairing cover plate damage in the direction of travel of the belt; | AD38: Pour réparer les dommages de la plaque de couverture dans le sens de déplacement de la bande ; | AE38: 5315731CH ; 5317722CH ; 5061984DE ; 5148760DE | AG38: 081 | AH38: 088 | AI38: 024 | AJ38: Reparaturband
A39: 5317722CH | B39: T-Rex Repair Strip Nr 0 -10.000x70x2,2 mm | C39: 0,000 | D39: 37, Tip Top | E39: 12021, REMA TIP TOP (Tianjin) Rubber Technology Co., Ltd. | F39: Actief | G39: 27,610 | H39: 43.9 | I39: 07_Repair Material | J39: 07-05_T-Rex Repair Strips | K39: T-REX Reparatie strip 70mm ; Zonder weefselinlage | L39: T-REX Reparaturband 70mm ; Ohne Gewebeeinlage | M39: T-REX Repair strip 70mm ; Without fabric reinforced | N39: T-REX Bande de réparation 70mm ; Sans pli renforcé | O39: Nr. 0 ; Afmeting: 10.000 x 70 mm ; Dikte: 2,2 mm ; Zonder weefselinlage ; Kleur: Zwart | P39: Nr. 0 ; Abmessung: 10.000 x 70 mm ; Starke: 2,2 mm ; Ohne Gewebeeinlage ; Farbe: Schwarz | Q39: Nr. 0 ; Dimensions: 10.000 x 70 mm ; Thickness: 2,2 mm ; Without fabric ; Colour: Black | R39: Nr. 0 ; Dimensions : 10.000 x 70 mm ; Epaisseur : 2,2 mm ; Sans pli ; Couleur : Noir | AA39: Voor het repareren van dekplaatbeschadigingen in de looprichting van de band; | AB39: Für die Reparatur von Deckplattenschäden in Gurtlaufrichtung ; | AC39: For repairing cover plate damage in the direction of travel of the belt; | AD39: Pour réparer les dommages de la plaque de couverture dans le sens de déplacement de la bande ; | AE39: 5317720CH ; 5315731CH ; 5061984DE ; 5148760DE | AG39: 081 | AH39: 088 | AI39: 024 | AJ39: Reparaturband
A40: 5317739CH | B40: T-Rex Repair Strip Nr 1 -10.000x100x2,2 mm | C40: 0,000 | D40: 37, Tip Top | E40: 12021, REMA TIP TOP (Tianjin) Rubber Technology Co., Ltd. | F40: Actief | G40: 33,790 | H40: 54.9 | I40: 07_Repair Material | J40: 07-05_T-Rex Repair Strips | K40: T-REX Reparatie strip 100mm ; Zonder weefselinlage | L40: T-REX Reparaturband 100mm ; Ohne Gewebeeinlage | M40: T-REX Repair strip 100mm ; Without fabric reinforced | N40: T-REX Bande de réparation 100mm ; Sans pli renforcé | O40: Nr. 1 ; Afmeting: 10.000 x 100 mm ; Dikte: 2,2 mm ; Zonder weefselinlage ; Kleur: Zwart | P40: Nr. 1 ; Abmessung: 10.000 x 100 mm ; Starke: 2,2 mm ; Ohne Gewebeeinlage ; Farbe: Schwarz | Q40: Nr. 1 ; Dimensions: 10.000 x 100 mm ; Thickness: 2,2 mm ; Without fabric ; Colour: Black | R40: Nr. 1 ; Dimensions : 10.000 x 100 mm ; Epaisseur : 2,2 mm ; Sans pli ; Couleur : Noir | AA40: Voor het repareren van dekplaatbeschadigingen in de looprichting van de band; | AB40: Für die Reparatur von Deckplattenschäden in Gurtlaufrichtung ; | AC40: For repairing cover plate damage in the direction of travel of the belt; | AD40: Pour réparer les dommages de la plaque de couverture dans le sens de déplacement de la bande ; | AE40: 5317722CH ; 5315731CH ; 5061984DE ; 5148760DE | AG40: 081 | AH40: 088 | AI40: 024 | AJ40: Reparaturband
...

Sheet Produktkategorien EN
A1: Hoofdcategorie | B1: Subcategorie | C1: Hoofdcategorie | D1: Subcategorie | E1: Hoofdcategorie | F1: Subcategorie | G1: Hoofdcategorie | H1: Subcategorie
A2: 01_Conveyor Belts | B2: 01-01_Anti Abrasion | C2: 01_Fördergurte | D2: 01-01_Abriebfest | E2: 01_Bandes transporteuses | F2: 01-01_Anti Abrasion | G2: 01_Transportbanden | H2: 01-01_Slijtbestendig
A3: 02_Profiled Conveyor Belts | B3: 01-02_Heat Resistant | C3: 02_Chevron Fördergurte | D3: 01-02_Hitzebeständig | E3: 02_Bandes transporteuses à Chevrons | F3: 01-02_Anti-chaleur | G3: 02_Transportbanden met profiel | H3: 01-02_Hittebestendig
A4: 03_Wear Protection | B4: 01-03_Oil and Grease Resistant | C4: 03_Verschleißschutz | D4: 01-03_Öl- und Fettbeständig | E4: 03_Protection anti-usure | F4: 01-03_Résistant aux huiles et graisses | G4: 03_Bescherming tegen slijtage | H4: 01-03_Olie- en vetbestendig
A5: 04_Drum Lagging | B5: 01-04_Bareback | C5: 04_Trommelbeläge | D5: 01-04_Gleitfördergurte | E5: 04_Garnissage pour tambour | F5: 01-04_Bandes sole de glisse | G5: 04_Trommelbekleding | H5: 01-04_Glijbanden
A6: 05_Tools | B6: 01-05_Ripstop | C6: 05_Werkzeuge | D6: 01-05_Ripstop | E6: 05_Outillage | F6: 01-05_Ripstop / Bande a breaker | G6: 05_Gereedschap | H6: 01-05_Ripstop
A7: 06_Vulcanization Materials | B7: 01-06_Supergrip Black | C7: 06_Vulkanisiermaterialen | D7: 01-06_Supergrip Schwarz | E7: 06_Matériaux de vulcanisation | F7: 01-06_Supergrip Noir | G7: 06_Vulkanisatiemateriaal | H7: 01-06_Supergrip Zwart
A8: 07_Repair Material | B8: 01-07_Supergrip Beige | C8: 07_Reparaturmaterial | D8: 01-07_Supergrip Beige | E8: 07_Matériaux de réparation | F8: 01-07_Supergrip Beige | G8: 07_Reparatiemateriaal | H8: 01-07_Supergrip Beige
A9: 08_Belt Cleaning | B9: 01-08_Elevator | C9: 08_Fördergurt-Reinigungssysteme | D9: 01-08_Elevator | E9: 08_Nettoyage bande transporteuse | F9: 01-08_Sangles élévatrices | G9: 08_Transportbandreiniging | H9: 01-08_Elevatorbanden
A10: 09_Components | B10: 01-09_Cross-Stable | C10: 09_Komponenten | D10: 01-09_Quersteif | E10: 09_Composants | F10: 01-09_Cross-Rigid | G10: 09_Componenten | H10: 01-09_Dwarsstabiel
A11: 10_Belt Tracking | B11: 01-10_T-Flex | C11: 10_Fördergurt-Zentrierung | D11: 01-10_T-Flex | E11: 10_Centrage de bande transporteuse | F11: 01-10_T-Flex | G11: 10_Transportbandstuursystemen | H11: 01-10_T-Flex
A12: 11_TQ Rollers | B12: 01-11_Saw Mill | C12: 11_TQ Rolle | D12: 01-11_Holz | E12: 11_TQ rouleaux | F12: 01-11_Bandes pour scieries | G12: 11_TQ Rollen | H12: 01-11_Saw Mill
A13: 12_Safety Products | B13: 01-12_Round Baler | C13: 12_Schutzvorrichtungen | D13: 01-12_Rundballenpresse | E13: 12_Produits de sécurité | F13: 01-12_Courroies Round Balers | G13: 12_Veiligheidsproducten | H13: 01-12_Round Baler
B14: 02-01_Profile height 6 – 13½ mm | D14: 02-01_Profilhöhe 6 – 13½ mm | F14: 02-01_Bandes à Chevrons, hauteur du profil 6 - 13½ mm | H14: 02-01_Profiel hoogte 6 – 13½ mm
B15: 02-02_Profile height 15 mm | D15: 02-02_Profilhöhe 15 mm | F15: 02-02_Bandes à Chevrons, hauteur du profil 15 mm | H15: 02-02_Profiel hoogte 15 mm
B16: 02-03_Profile height 17 mm | D16: 02-03_Profilhöhe 17 mm | F16: 02-03_Bandes à Chevrons, hauteur du profil 17 mm | H16: 02-03_Profiel hoogte 17 mm
B17: 02-04_Profile height 25 mm | D17: 02-04_Profilhöhe 25 mm | F17: 02-04_Bandes à Chevrons, hauteur du profil 25 mm | H17: 02-04_Profiel hoogte 25 mm
B18: 02-05_Profile height 32 mm | D18: 02-05_Profilhöhe 32 mm | F18: 02-05_Bandes à Chevrons, hauteur du profil 32 mm | H18: 02-05_Profiel hoogte 32 mm
B19: 02-06_Oil and Grease Resistant | D19: 02-06_ Öl und fettbeständig | F19: 02-06_Bandes à chevrons, résistant aux huiles et graisses | H19: 02-06_Olie- en vetbestendig
B20: 02-07_Salt | D20: 02-07_Salz | F20: 02-07_Bandes pour saleuses | H20: 02-07_Zoutbanden
B21: 03-01_T-REX40 with Bonding Layer | D21: 03-01_T-REX40 mit Kontaktschicht | F21: 03-01_T-REX40 avec face adhésive | H21: 03-01_T-REX40 met Lijmlaag
B22: 03-02_T-REX40 without Bonding Layer | D22: 03-02_T-REX40 ohne Kontaktschicht | F22: 03-02_T-REX40 sans face adhésive | H22: 03-02_T-REX40 zonder Lijmlaag
B23: 03-03_T-REX40 Side Skirt Rubber | D23: 03-03_T-REX40 Seitenführungsgummi | F23: 03-03_T-REX40 Bavettes | H23: 03-03_T-REX40 Zijgeleidingsrubber
B24: 03-04_T-REX50 with Bonding Layer | D24: 03-04_T-REX50 mit Kontaktschicht | F24: 03-04_T-REX50 avec face adhésive | H24: 03-04_T-REX50 met Lijmlaag
B25: 03-05_T-REX50 without Bonding Layer | D25: 03-05_T-REX50 ohne Kontaktschicht | F25: 03-05_T-REX50 sans face adhésive | H25: 03-05_T-REX50 zonder Lijmlaag
... B90: 12-04_Inspection Door + Screen | D90: 12-04_Inspektionstür + Fenster | F90: 12-04_Inspection par | H90: 12-04_Inspectiedeuren

Sheet INPUT MA
A1: Webshop laag 0 | B1: Code laag 1 | C1: Webshop laag 1 EN | D1: Webshop laag 1 NL | E1: Webshop laag 1 FR | F1: Webshop laag 1 DE | G1: Code laag 2 | H1: Webshop laag 2 EN | I1: Webshop laag 2 NL | J1: Webshop laag 2 FR | K1: Webshop laag 2 DE
B2: A | C2: 01_Conveyor Belts | D2: =IFERROR(VLOOKUP(C2,'Produktkategorien EN'!A:H,7,FALSE),"") -> 01_Transportbanden | E2: =IFERROR(VLOOKUP(C2,'Produktkategorien EN'!A:H,5,FALSE),"") -> 01_Bandes transporteuses | F2: =IFERROR(VLOOKUP(C2,'Produktkategorien EN'!A:H,3,FALSE),"") -> 01_Fördergurte | G2: A1 | H2: 01-01_Anti Abrasion | I2: 01-01_Slijtbestendig | J2: 01-01_Anti Abrasion | K2: 01-01_Abriebfest
B3: A | D3: =IFERROR(VLOOKUP(C3,'Produktkategorien EN'!A:H,7,FALSE),"") | E3: =IFERROR(VLOOKUP(C3,'Produktkategorien EN'!A:H,5,FALSE),"") | F3: =IFERROR(VLOOKUP(C3,'Produktkategorien EN'!A:H,3,FALSE),"") | G3: A2 | H3: 01-02_Heat Resistant | I3: 01-02_Hittebestendig | J3: 01-02_anti-chaleur | K3: 01-02_Hitzebeständig
B4: A | D4: =IFERROR(VLOOKUP(C4,'Produktkategorien EN'!A:H,7,FALSE),"") | E4: =IFERROR(VLOOKUP(C4,'Produktkategorien EN'!A:H,5,FALSE),"") | F4: =IFERROR(VLOOKUP(C4,'Produktkategorien EN'!A:H,3,FALSE),"") | G4: A3 | H4: 01-03_Oil and Grease Resistant | I4: 01-03_Olie- en vetbestendig | J4: 01-03_résistant aux huiles et graisses | K4: 01-03_Öl- und Fettbeständig
B5: A | D5: =IFERROR(VLOOKUP(C5,'Produktkategorien EN'!A:H,7,FALSE),"") | E5: =IFERROR(VLOOKUP(C5,'Produktkategorien EN'!A:H,5,FALSE),"") | F5: =IFERROR(VLOOKUP(C5,'Produktkategorien EN'!A:H,3,FALSE),"") | G5: A4 | H5: 01-04_Bareback | I5: 01-04_Glijbanden | J5: 01-04_Bandes glissantes | K5: 01-04_Gleitfördergurte
B6: A | D6: =IFERROR(VLOOKUP(C6,'Produktkategorien EN'!A:H,7,FALSE),"") | E6: =IFERROR(VLOOKUP(C6,'Produktkategorien EN'!A:H,5,FALSE),"") | F6: =IFERROR(VLOOKUP(C6,'Produktkategorien EN'!A:H,3,FALSE),"") | G6: A5 | H6: 01-05_Ripstop | I6: 01-05_Ripstop | J6: 01-05_Ripstop | K6: 01-05_Ripstop
B7: A | D7: =IFERROR(VLOOKUP(C7,'Produktkategorien EN'!A:H,7,FALSE),"") | E7: =IFERROR(VLOOKUP(C7,'Produktkategorien EN'!A:H,5,FALSE),"") | F7: =IFERROR(VLOOKUP(C7,'Produktkategorien EN'!A:H,3,FALSE),"") | G7: A6 | H7: 01-06_Supergrip Black | I7: 01-06_Supergrip Zwart | J7: 01-06_Supergrip Noir | K7: 01-06_Supergrip Schwarz
B8: A | D8: =IFERROR(VLOOKUP(C8,'Produktkategorien EN'!A:H,7,FALSE),"") | E8: =IFERROR(VLOOKUP(C8,'Produktkategorien EN'!A:H,5,FALSE),"") | F8: =IFERROR(VLOOKUP(C8,'Produktkategorien EN'!A:H,3,FALSE),"") | G8: A7 | H8: 01-07_Supergrip Beige | I8: 01-07_Supergrip Beige | J8: 01-07_Supergrip Beige | K8: 01-07_Supergrip Beige
B9: A | D9: =IFERROR(VLOOKUP(C9,'Produktkategorien EN'!A:H,7,FALSE),"") | E9: =IFERROR(VLOOKUP(C9,'Produktkategorien EN'!A:H,5,FALSE),"") | F9: =IFERROR(VLOOKUP(C9,'Produktkategorien EN'!A:H,3,FALSE),"") | G9: A8 | H9: 01-08_Elevator | I9: 01-08_Elevatorbanden | J9: 01-08_Sangles élévatrices | K9: 01-08_Elevator
B10: A | D10: =IFERROR(VLOOKUP(C10,'Produktkategorien EN'!A:H,7,FALSE),"") | E10: =IFERROR(VLOOKUP(C10,'Produktkategorien EN'!A:H,5,FALSE),"") | F10: =IFERROR(VLOOKUP(C10,'Produktkategorien EN'!A:H,3,FALSE),"") | G10: A9 | H10: 01-09_Cross-Stable | I10: 01-09_Dwarsstabiel | J10: 01-09_Cross-Rigid | K10: 01-09_Quersteif
B11: A | D11: =IFERROR(VLOOKUP(C11,'Produktkategorien EN'!A:H,7,FALSE),"") | E11: =IFERROR(VLOOKUP(C11,'Produktkategorien EN'!A:H,5,FALSE),"") | F11: =IFERROR(VLOOKUP(C11,'Produktkategorien EN'!A:H,3,FALSE),"") | G11: A10 | H11: 01-10_T-Flex | I11: 01-10_T-Flex | J11: 01-10_T-Flex | K11: 01-10_T-Flex
B12: A | D12: =IFERROR(VLOOKUP(C12,'Produktkategorien EN'!A:H,7,FALSE),"") | E12: =IFERROR(VLOOKUP(C12,'Produktkategorien EN'!A:H,5,FALSE),"") | F12: =IFERROR(VLOOKUP(C12,'Produktkategorien EN'!A:H,3,FALSE),"") | G12: A11 | H12: 01-11_Saw Mill | I12: 01-11_Saw Mill | J12: 01-11_Bandes pour scieries | K12: 01-11_Holz
B13: A | D13: =IFERROR(VLOOKUP(C13,'Produktkategorien EN'!A:H,7,FALSE),"") | E13: =IFERROR(VLOOKUP(C13,'Produktkategorien EN'!A:H,5,FALSE),"") | F13: =IFERROR(VLOOKUP(C13,'Produktkategorien EN'!A:H,3,FALSE),"") | G13: A12 | H13: 01-12_Round Baler | I13: 01-12_Round Baler | J13: 01-12_Courroies Round Balers | K13: 01-12_Rundballenpresse
B14: B | C14: 02_Profiled Conveyor Belts | D14: =IFERROR(VLOOKUP(C14,'Produktkategorien EN'!A:H,7,FALSE),"") -> 02_Transportbanden met profiel | E14: =IFERROR(VLOOKUP(C14,'Produktkategorien EN'!A:H,5,FALSE),"") -> 02_Bandes transporteuses à Chevrons | F14: =IFERROR(VLOOKUP(C14,'Produktkategorien EN'!A:H,3,FALSE),"") -> 02_Chevron Fördergurte | G14: B1 | H14: 02-01_Profile height 6 – 13½ mm | I14: 02-01_Profiel hoogte 6 – 13½ mm | J14: 02-01_Bandes à Chevrons, hauteur du profil 6 - 13½ mm | K14: 02-01_Profilhöhe 6 – 13½ mm
B15: B | D15: =IFERROR(VLOOKUP(C15,'Produktkategorien EN'!A:H,7,FALSE),"") | E15: =IFERROR(VLOOKUP(C15,'Produktkategorien EN'!A:H,5,FALSE),"") | F15: =IFERROR(VLOOKUP(C15,'Produktkategorien EN'!A:H,3,FALSE),"") | G15: B2 | H15: 02-02_Profile height 15 mm | I15: 02-02_Profiel hoogte 15 mm | J15: 02-02_Bandes à Chevrons, hauteur du profil 15 mm | K15: 02-02_Profilhöhe 15 mm
B16: B | D16: =IFERROR(VLOOKUP(C16,'Produktkategorien EN'!A:H,7,FALSE),"") | E16: =IFERROR(VLOOKUP(C16,'Produktkategorien EN'!A:H,5,FALSE),"") | F16: =IFERROR(VLOOKUP(C16,'Produktkategorien EN'!A:H,3,FALSE),"") | G16: B3 | H16: 02-03_Profile height 17 mm | I16: 02-03_Profiel hoogte 17 mm | J16: 02-03_Bandes à Chevrons, hauteur du profil 17 mm | K16: 02-03_Profilhöhe 17 mm
B17: B | D17: =IFERROR(VLOOKUP(C17,'Produktkategorien EN'!A:H,7,FALSE),"") | E17: =IFERROR(VLOOKUP(C17,'Produktkategorien EN'!A:H,5,FALSE),"") | F17: =IFERROR(VLOOKUP(C17,'Produktkategorien EN'!A:H,3,FALSE),"") | G17: B4 | H17: 02-04_Profile height 25 mm | I17: 02-04_Profiel hoogte 25 mm | J17: 02-04_Bandes à Chevrons, hauteur du profil 25 mm | K17: 02-04_Profilhöhe 25 mm
B18: B | D18: =IFERROR(VLOOKUP(C18,'Produktkategorien EN'!A:H,7,FALSE),"") | E18: =IFERROR(VLOOKUP(C18,'Produktkategorien EN'!A:H,5,FALSE),"") | F18: =IFERROR(VLOOKUP(C18,'Produktkategorien EN'!A:H,3,FALSE),"") | G18: B5 | H18: 02-05_Profile height 32 mm | I18: 02-05_Profiel hoogte 32 mm | J18: 02-05_Bandes à Chevrons, hauteur du profil 32 mm | K18: 02-05_Profilhöhe 32 mm
B19: B | D19: =IFERROR(VLOOKUP(C19,'Produktkategorien EN'!A:H,7,FALSE),"") | E19: =IFERROR(VLOOKUP(C19,'Produktkategorien EN'!A:H,5,FALSE),"") | F19: =IFERROR(VLOOKUP(C19,'Produktkategorien EN'!A:H,3,FALSE),"") | G19: B6 | H19: 02-06_Oil and Grease Resistant | I19: 02-06_Olie- en vetbestendig | J19: 02-06_Bandes à chevrons, résistant aux huiles et graisses | K19: 02-06_ Öl und fettbeständig
B20: B | D20: =IFERROR(VLOOKUP(C20,'Produktkategorien EN'!A:H,7,FALSE),"") | E20: =IFERROR(VLOOKUP(C20,'Produktkategorien EN'!A:H,5,FALSE),"") | F20: =IFERROR(VLOOKUP(C20,'Produktkategorien EN'!A:H,3,FALSE),"") | G20: B7 | H20: 02-07_Salt | I20: 02-07_Zoutbanden | J20: 02-07_Bandes pour saleuses | K20: 02-07_Salz
B21: C | C21: 03_Wear Protection | D21: =IFERROR(VLOOKUP(C21,'Produktkategorien EN'!A:H,7,FALSE),"") -> 03_Bescherming tegen slijtage | E21: =IFERROR(VLOOKUP(C21,'Produktkategorien EN'!A:H,5,FALSE),"") -> 03_Protection anti-usure | F21: =IFERROR(VLOOKUP(C21,'Produktkategorien EN'!A:H,3,FALSE),"") -> 03_Verschleißschutz | G21: C1 | H21: 03-01_T-REX40 with Bonding Layer | I21: 03-01_T-REX40 met Lijmlaag | J21: 03-01_T-REX40 avec face adhésive | K21: 03-01_T-REX40 mit Kontaktschicht
B22: C | D22: =IFERROR(VLOOKUP(C22,'Produktkategorien EN'!A:H,7,FALSE),"") | E22: =IFERROR(VLOOKUP(C22,'Produktkategorien EN'!A:H,5,FALSE),"") | F22: =IFERROR(VLOOKUP(C22,'Produktkategorien EN'!A:H,3,FALSE),"") | G22: C2 | H22: 03-02_T-REX40 without Bonding Layer | I22: 03-02_T-REX40 zonder Lijmlaag | J22: 03-02_T-REX40 sans face adhésive | K22: 03-02_T-REX40 ohne Kontaktschicht
B23: C | D23: =IFERROR(VLOOKUP(C23,'Produktkategorien EN'!A:H,7,FALSE),"") | E23: =IFERROR(VLOOKUP(C23,'Produktkategorien EN'!A:H,5,FALSE),"") | F23: =IFERROR(VLOOKUP(C23,'Produktkategorien EN'!A:H,3,FALSE),"") | G23: C3 | H23: 03-03_T-REX40 Side Skirt Rubber | I23: 03-03_T-REX40 Zijgeleidingsrubber | J23: 03-03_T-REX40 Bavettes | K23: 03-03_T-REX40 Seitenführungsgummi
B24: C | D24: =IFERROR(VLOOKUP(C24,'Produktkategorien EN'!A:H,7,FALSE),"") | E24: =IFERROR(VLOOKUP(C24,'Produktkategorien EN'!A:H,5,FALSE),"") | F24: =IFERROR(VLOOKUP(C24,'Produktkategorien EN'!A:H,3,FALSE),"") | G24: C4 | H24: 03-04_T-REX50 with Bonding Layer | I24: 03-04_T-REX50 met Lijmlaag | J24: 03-04_T-REX50 avec face adhésive | K24: 03-04_T-REX50 mit Kontaktschicht
B25: C | D25: =IFERROR(VLOOKUP(C25,'Produktkategorien EN'!A:H,7,FALSE),"") | E25: =IFERROR(VLOOKUP(C25,'Produktkategorien EN'!A:H,5,FALSE),"") | F25: =IFERROR(VLOOKUP(C25,'Produktkategorien EN'!A:H,3,FALSE),"") | G25: C5 | H25: 03-05_T-REX50 without Bonding Layer | I25: 03-05_T-REX50 zonder Lijmlaag | J25: 03-05_T-REX50 sans face adhésive | K25: 03-05_T-REX50 ohne Kontaktschicht
B26: C | D26: =IFERROR(VLOOKUP(C26,'Produktkategorien EN'!A:H,7,FALSE),"") | E26: =IFERROR(VLOOKUP(C26,'Produktkategorien EN'!A:H,5,FALSE),"") | F26: =IFERROR(VLOOKUP(C26,'Produktkategorien EN'!A:H,3,FALSE),"") | G26: C6 | H26: 03-06_T-REX50 Side Skirt Rubber | I26: 03-06_T-REX50 Zijgeleidingsrubber | J26: 03-06_T-REX50 Bavettes | K26: 03-06_T-REX50 Seitenführungsgummi
B27: C | D27: =IFERROR(VLOOKUP(C27,'Produktkategorien EN'!A:H,7,FALSE),"") | E27: =IFERROR(VLOOKUP(C27,'Produktkategorien EN'!A:H,5,FALSE),"") | F27: =IFERROR(VLOOKUP(C27,'Produktkategorien EN'!A:H,3,FALSE),"") | G27: C7 | H27: 03-07_T-REX60 with Bonding Layer | I27: 03-07_T-REX60 met Lijmlaag | J27: 03-07_T-REX60 avec face adhésive | K27: 03-07_T-REX60 mit Kontaktschicht
B28: C | D28: =IFERROR(VLOOKUP(C28,'Produktkategorien EN'!A:H,7,FALSE),"") | E28: =IFERROR(VLOOKUP(C28,'Produktkategorien EN'!A:H,5,FALSE),"") | F28: =IFERROR(VLOOKUP(C28,'Produktkategorien EN'!A:H,3,FALSE),"") | G28: C8 | H28: 03-08_T-REX60 without Bonding Layer | I28: 03-08_T-REX60 zonder Lijmlaag | J28: 03-08_T-REX60 sans face adhésive | K28: 03-08_T-REX60 ohne Kontaktschicht
B29: C | D29: =IFERROR(VLOOKUP(C29,'Produktkategorien EN'!A:H,7,FALSE),"") | E29: =IFERROR(VLOOKUP(C29,'Produktkategorien EN'!A:H,5,FALSE),"") | F29: =IFERROR(VLOOKUP(C29,'Produktkategorien EN'!A:H,3,FALSE),"") | G29: C9 | H29: 03-09_T-REX60 Side Skirt Rubber | I29: 03-09_T-REX60 Zijgeleidingsrubber | J29: 03-09_T-REX60 Bavettes | K29: 03-09_T-REX60 Seitenführungsgummi
B30: C | D30: =IFERROR(VLOOKUP(C30,'Produktkategorien EN'!A:H,7,FALSE),"") | E30: =IFERROR(VLOOKUP(C30,'Produktkategorien EN'!A:H,5,FALSE),"") | F30: =IFERROR(VLOOKUP(C30,'Produktkategorien EN'!A:H,3,FALSE),"") | G30: C10 | H30: 03-10_LINA-REX | I30: 03-10_LINA-REX | J30: 03-10_LINA-REX | K30: 03-10_LINA-REX
B31: C | D31: =IFERROR(VLOOKUP(C31,'Produktkategorien EN'!A:H,7,FALSE),"") | E31: =IFERROR(VLOOKUP(C31,'Produktkategorien EN'!A:H,5,FALSE),"") | F31: =IFERROR(VLOOKUP(C31,'Produktkategorien EN'!A:H,3,FALSE),"") | G31: C11 | H31: 03-11_Caramel | I31: 03-11_Karamel | J31: 03-11_Caramel | K31: 03-11_Karamel
B32: C | D32: =IFERROR(VLOOKUP(C32,'Produktkategorien EN'!A:H,7,FALSE),"") | E32: =IFERROR(VLOOKUP(C32,'Produktkategorien EN'!A:H,5,FALSE),"") | F32: =IFERROR(VLOOKUP(C32,'Produktkategorien EN'!A:H,3,FALSE),"") | G32: C12 | H32: 03-12_Economy Rubber Sheets | I32: 03-12_Economy Slijtvast | J32: 03-12_Economy Caoutchouc | K32: 03-12_Economy gummiplatten
B33: D | C33: 04_Drum Lagging | D33: =IFERROR(VLOOKUP(C33,'Produktkategorien EN'!A:H,7,FALSE),"") -> 04_Trommelbekleding | E33: =IFERROR(VLOOKUP(C33,'Produktkategorien EN'!A:H,5,FALSE),"") -> 04_Garnissage pour tambour | F33: =IFERROR(VLOOKUP(C33,'Produktkategorien EN'!A:H,3,FALSE),"") -> 04_Trommelbeläge | G33: D1 | H33: 04-01_Mini Diamond Black | I33: 04-01_Mini Diamond Zwart | J33: 04-01_Mini Losange noir | K33: 04-01_Mini Raute Schwarz
